Workbook

Sheet Dashboard
B1: MANSI CHEMICALS | Sales & Operations Dashboard | T1: Solvent Soluble Dyes · Jan 2023 – Jun 2024
B4: Region filter ▶ | D4: All | F4: Year ▶ | H4: All | J4: (pick Region and/or Year – the dashboard updates)
B6: TOTAL REVENUE | F6: VOLUME SOLD | J6: GROSS MARGIN | N6: ORDERS | R6: AVG SELLING PRICE | V6: ON-TIME DELIVERY
B7: =Calc!$B$124 -> 220.34375 | F7: =Calc!$B$125 -> 23975 | J7: =Calc!$B$127 -> 0.27274883 | N7: =Calc!$B$128 -> 200 | R7: =Calc!$B$129 -> 919.05631 | V7: =Calc!$B$132 -> 0.79274611
B9: ="Avg order ₹ "&TEXT(Calc!$B$124*100000/Calc!$B$128/1000,"0.0")&"K" -> Avg order ₹ 110.2K | F9: ="Export share "&TEXT(Calc!$B$133,"0%")&" of total" -> Export share 59% of total | J9: ="₹ "&TEXT(Calc!$B$126,"0.0")&" Lakh" -> ₹ 60.1 Lakh | N9: =Calc!$B$134&" open (not dispatched)" -> 7 open (not dispatched) | R9: across all shades | V9: ="Avg lead time "&TEXT(Calc!$B$135,"0.0")&" days" -> Avg lead time 17.8 days
B60: =Calc!L33 -> Like-for-like Jan–Jun: 2023 ₹ 66.6 L vs 2024 ₹ 74.9 L (+12.5%)
B78: Sample dashboard built on simulated data modelled on the Mansi Chemicals product range (37 shades from the shade card). Figures are illustrative, not actual company results.

Sheet Sales_Data
A1: Order ID | B1: Order Date | C1: Month | D1: Customer | E1: Region | F1: State / Country | G1: Product Code | H1: Product (Shade) | I1: C.I. Name | J1: Shade Family | K1: Application Segment | L1: Qty (kg) | M1: Rate (₹/kg) | N1: Sales Value (₹) | O1: Unit Cost (₹/kg) | P1: Gross Margin (₹) | Q1: Promised Lead Time (days) | R1: Actual Lead Time (days) | S1: Status | T1: On-Time? | U1: Year
A2: MC-23-0001 | B2: 44930 | C2: =IF(B2="","",DATE(YEAR(B2),MONTH(B2),1)) -> 44927 | D2: Sao Paulo Foil Tech Ltda | E2: Export | F2: Brazil | G2: MC-30 | H2: Brown 287-L | I2: - | J2: Brown | K2: Hot Foil Stamping | L2: 300 | M2: 805 | N2: =IF(L2="","",L2*M2) -> 241500 | O2: 604 | P2: =IF(L2="","",N2-L2*O2) -> 60300 | Q2: 30 | R2: 29 | S2: Delivered | T2: =IF(R2="","",IF(R2<=Q2,"Yes","No")) -> Yes | U2: =IF(B2="","",TEXT(YEAR(B2),"0")) -> 2023
A3: MC-23-0002 | B3: 44930 | C3: =IF(B3="","",DATE(YEAR(B3),MONTH(B3),1)) -> 44927 | D3: Pioneer Foils & Films Pvt. Ltd. | E3: Domestic | F3: Maharashtra | G3: MC-06 | H3: Golden Yellow | I3: - | J3: Yellow | K3: Metallised Film & Foil Coating | L3: 25 | M3: 815 | N3: =IF(L3="","",L3*M3) -> 20375 | O3: 567 | P3: =IF(L3="","",N3-L3*O3) -> 6200 | Q3: 15 | R3: 14 | S3: Delivered | T3: =IF(R3="","",IF(R3<=Q3,"Yes","No")) -> Yes | U3: =IF(B3="","",TEXT(YEAR(B3),"0")) -> 2023
A4: MC-23-0003 | B4: 44931 | C4: =IF(B4="","",DATE(YEAR(B4),MONTH(B4),1)) -> 44927 | D4: Sri Lakshmi Leather Chemicals | E4: Domestic | F4: Tamil Nadu | G4: MC-03 | H4: Yellow GL | I4: C.I. Solvent Yellow 90 | J4: Yellow | K4: Leather Finishing | L4: 50 | M4: 750 | N4: =IF(L4="","",L4*M4) -> 37500 | O4: 553 | P4: =IF(L4="","",N4-L4*O4) -> 9850 | Q4: 15 | R4: 12 | S4: Delivered | T4: =IF(R4="","",IF(R4<=Q4,"Yes","No")) -> Yes | U4: =IF(B4="","",TEXT(YEAR(B4),"0")) -> 2023
A5: MC-23-0004 | B5: 44932 | C5: =IF(B5="","",DATE(YEAR(B5),MONTH(B5),1)) -> 44927 | D5: Guangzhou Huaxin Coatings Co., Ltd. | E5: Export | F5: China | G5: MC-21 | H5: Black RE | I5: C.I. Solvent Black 27 | J5: Black | K5: Aluminium & Metal Coating | L5: 25 | M5: 680 | N5: =IF(L5="","",L5*M5) -> 17000 | O5: 542 | P5: =IF(L5="","",N5-L5*O5) -> 3450 | Q5: 21 | R5: 21 | S5: Delivered | T5: =IF(R5="","",IF(R5<=Q5,"Yes","No")) -> Yes | U5: =IF(B5="","",TEXT(YEAR(B5),"0")) -> 2023
A6: MC-23-0005 | B6: 44935 | C6: =IF(B6="","",DATE(YEAR(B6),MONTH(B6),1)) -> 44927 | D6: Ningbo Metallic Film Co., Ltd. | E6: Export | F6: China | G6: MC-06 | H6: Golden Yellow | I6: - | J6: Yellow | K6: Metallised Film & Foil Coating | L6: 100 | M6: 750 | N6: =IF(L6="","",L6*M6) -> 75000 | O6: 575 | P6: =IF(L6="","",N6-L6*O6) -> 17500 | Q6: 25 | R6: 22 | S6: Delivered | T6: =IF(R6="","",IF(R6<=Q6,"Yes","No")) -> Yes | U6: =IF(B6="","",TEXT(YEAR(B6),"0")) -> 2023
A7: MC-23-0006 | B7: 44936 | C7: =IF(B7="","",DATE(YEAR(B7),MONTH(B7),1)) -> 44927 | D7: Bangkok Ink & Resin Co., Ltd. | E7: Export | F7: Thailand | G7: MC-01 | H7: Yellow 2RLS | I7: C.I. Solvent Yellow 62 | J7: Yellow | K7: Printing Inks (Flexo / Gravure) | L7: 25 | M7: 770 | N7: =IF(L7="","",L7*M7) -> 19250 | O7: 591 | P7: =IF(L7="","",N7-L7*O7) -> 4475 | Q7: 30 | R7: 29 | S7: Delivered | T7: =IF(R7="","",IF(R7<=Q7,"Yes","No")) -> Yes | U7: =IF(B7="","",TEXT(YEAR(B7),"0")) -> 2023
A8: MC-23-0007 | B8: 44937 | C8: =IF(B8="","",DATE(YEAR(B8),MONTH(B8),1)) -> 44927 | D8: Bangkok Ink & Resin Co., Ltd. | E8: Export | F8: Thailand | G8: MC-28 | H8: Purple | I8: - | J8: Blue / Violet | K8: Printing Inks (Flexo / Gravure) | L8: 100 | M8: 1210 | N8: =IF(L8="","",L8*M8) -> 121000 | O8: 868 | P8: =IF(L8="","",N8-L8*O8) -> 34200 | Q8: 30 | R8: 26 | S8: Delivered | T8: =IF(R8="","",IF(R8<=Q8,"Yes","No")) -> Yes | U8: =IF(B8="","",TEXT(YEAR(B8),"0")) -> 2023
A9: MC-23-0008 | B9: 44938 | C9: =IF(B9="","",DATE(YEAR(B9),MONTH(B9),1)) -> 44927 | D9: Sri Lakshmi Leather Chemicals | E9: Domestic | F9: Tamil Nadu | G9: MC-20 | H9: Jet Black | I9: - | J9: Black | K9: Metallised Film & Foil Coating | L9: 300 | M9: 610 | N9: =IF(L9="","",L9*M9) -> 183000 | O9: 483 | P9: =IF(L9="","",N9-L9*O9) -> 38100 | Q9: 10 | R9: 12 | S9: Delivered | T9: =IF(R9="","",IF(R9<=Q9,"Yes","No")) -> No | U9: =IF(B9="","",TEXT(YEAR(B9),"0")) -> 2023
A10: MC-23-0009 | B10: 44939 | C10: =IF(B10="","",DATE(YEAR(B10),MONTH(B10),1)) -> 44927 | D10: Guangzhou Huaxin Coatings Co., Ltd. | E10: Export | F10: China | G10: MC-05 | H10: Yellow 2R | I10: C.I. Solvent Orange 45 | J10: Yellow | K10: Aluminium & Metal Coating | L10: 100 | M10: 810 | N10: =IF(L10="","",L10*M10) -> 81000 | O10: 603 | P10: =IF(L10="","",N10-L10*O10) -> 20700 | Q10: 30 | R10: 29 | S10: Delivered | T10: =IF(R10="","",IF(R10<=Q10,"Yes","No")) -> Yes | U10: =IF(B10="","",TEXT(YEAR(B10),"0")) -> 2023
A11: MC-23-0010 | B11: 44942 | C11: =IF(B11="","",DATE(YEAR(B11),MONTH(B11),1)) -> 44927 | D11: Guangzhou Huaxin Coatings Co., Ltd. | E11: Export | F11: China | G11: MC-23 | H11: Black RBL | I11: C.I. Solvent Black 34 | J11: Black | K11: Printing Inks (Flexo / Gravure) | L11: 100 | M11: 640 | N11: =IF(L11="","",L11*M11) -> 64000 | O11: 509 | P11: =IF(L11="","",N11-L11*O11) -> 13100 | Q11: 21 | R11: 17 | S11: Delivered | T11: =IF(R11="","",IF(R11<=Q11,"Yes","No")) -> Yes | U11: =IF(B11="","",TEXT(YEAR(B11),"0")) -> 2023
A12: MC-23-0011 | B12: 44960 | C12: =IF(B12="","",DATE(YEAR(B12),MONTH(B12),1)) -> 44958 | D12: Sao Paulo Foil Tech Ltda | E12: Export | F12: Brazil | G12: MC-31 | H12: Brown GLW | I12: - | J12: Brown | K12: Metallised Film & Foil Coating | L12: 100 | M12: 830 | N12: =IF(L12="","",L12*M12) -> 83000 | O12: 616 | P12: =IF(L12="","",N12-L12*O12) -> 21400 | Q12: 30 | R12: 29 | S12: Delivered | T12: =IF(R12="","",IF(R12<=Q12,"Yes","No")) -> Yes | U12: =IF(B12="","",TEXT(YEAR(B12),"0")) -> 2023
A13: MC-23-0012 | B13: 44961 | C13: =IF(B13="","",DATE(YEAR(B13),MONTH(B13),1)) -> 44958 | D13: Marudhar Paints & Coatings Pvt. Ltd. | E13: Domestic | F13: Rajasthan | G13: MC-01 | H13: Yellow 2RLS | I13: C.I. Solvent Yellow 62 | J13: Yellow | K13: Aluminium & Metal Coating | L13: 50 | M13: 820 | N13: =IF(L13="","",L13*M13) -> 41000 | O13: 590 | P13: =IF(L13="","",N13-L13*O13) -> 11500 | Q13: 10 | R13: 7 | S13: Delivered | T13: =IF(R13="","",IF(R13<=Q13,"Yes","No")) -> Yes | U13: =IF(B13="","",TEXT(YEAR(B13),"0")) -> 2023
... A191: MC-24-0190 | B191: 45443 | C191: =IF(B191="","",DATE(YEAR(B191),MONTH(B191),1)) -> 45413 | D191: Guangzhou Huaxin Coatings Co., Ltd. | E191: Export | F191: China | G191: MC-35 | H191: Green GL | I191: - | J191: Green | K191: Printing Inks (Flexo / Gravure) | L191: 200 | M191: 1045 | N191: =IF(L191="","",L191*M191) -> 209000 | O191: 746 | P191: =IF(L191="","",N191-L191*O191) -> 59800 | Q191: 30 | R191: 28 | S191: Delivered | T191: =IF(R191="","",IF(R191<=Q191,"Yes","No")) -> Yes | U191: =IF(B191="","",TEXT(YEAR(B191),"0")) -> 2024
A192: MC-24-0191 | B192: 45444 | C192: =IF(B192="","",DATE(YEAR(B192),MONTH(B192),1)) -> 45444 | D192: Ningbo Metallic Film Co., Ltd. | E192: Export | F192: China | G192: MC-21 | H192: Black RE | I192: C.I. Solvent Black 27 | J192: Black | K192: Printing Inks (Flexo / Gravure) | L192: 100 | M192: 740 | N192: =IF(L192="","",L192*M192) -> 74000 | O192: 551 | P192: =IF(L192="","",N192-L192*O192) -> 18900 | Q192: 30 | S192: Pending Dispatch | T192: =IF(R192="","",IF(R192<=Q192,"Yes","No")) | U192: =IF(B192="","",TEXT(YEAR(B192),"0")) -> 2024
A193: MC-24-0192 | B193: 45448 | C193: =IF(B193="","",DATE(YEAR(B193),MONTH(B193),1)) -> 45444 | D193: Krishna Print Inks Pvt. Ltd. | E193: Domestic | F193: Gujarat | G193: MC-20 | H193: Jet Black | I193: - | J193: Black | K193: Pen & Marker Inks | L193: 25 | M193: 695 | N193: =IF(L193="","",L193*M193) -> 17375 | O193: 511 | P193: =IF(L193="","",N193-L193*O193) -> 4600 | Q193: 10 | S193: Pending Dispatch | T193: =IF(R193="","",IF(R193<=Q193,"Yes","No")) | U193: =IF(B193="","",TEXT(YEAR(B193),"0")) -> 2024
A194: MC-24-0193 | B194: 45451 | C194: =IF(B194="","",DATE(YEAR(B194),MONTH(B194),1)) -> 45444 | D194: Saigon Coatings JSC | E194: Export | F194: Vietnam | G194: MC-24 | H194: Blue 2GLN | I194: C.I. Solvent Blue 48 | J194: Blue / Violet | K194: Aluminium & Metal Coating | L194: 100 | M194: 1350 | N194: =IF(L194="","",L194*M194) -> 135000 | O194: 900 | P194: =IF(L194="","",N194-L194*O194) -> 45000 | Q194: 25 | S194: Pending Dispatch | T194: =IF(R194="","",IF(R194<=Q194,"Yes","No")) | U194: =IF(B194="","",TEXT(YEAR(B194),"0")) -> 2024
A195: MC-24-0194 | B195: 45453 | C195: =IF(B195="","",DATE(YEAR(B195),MONTH(B195),1)) -> 45444 | D195: Pioneer Foils & Films Pvt. Ltd. | E195: Domestic | F195: Maharashtra | G195: MC-09 | H195: Orange 2R | I195: C.I. Solvent Orange 62 | J195: Orange | K195: Hot Foil Stamping | L195: 100 | M195: 1010 | N195: =IF(L195="","",L195*M195) -> 101000 | O195: 694 | P195: =IF(L195="","",N195-L195*O195) -> 31600 | Q195: 10 | R195: 10 | S195: Delivered | T195: =IF(R195="","",IF(R195<=Q195,"Yes","No")) -> Yes | U195: =IF(B195="","",TEXT(YEAR(B195),"0")) -> 2024
A196: MC-24-0195 | B196: 45454 | C196: =IF(B196="","",DATE(YEAR(B196),MONTH(B196),1)) -> 45444 | D196: Guangzhou Huaxin Coatings Co., Ltd. | E196: Export | F196: China | G196: MC-20 | H196: Jet Black | I196: - | J196: Black | K196: Pen & Marker Inks | L196: 200 | M196: 625 | N196: =IF(L196="","",L196*M196) -> 125000 | O196: 494 | P196: =IF(L196="","",N196-L196*O196) -> 26200 | Q196: 21 | R196: 14 | S196: Delivered | T196: =IF(R196="","",IF(R196<=Q196,"Yes","No")) -> Yes | U196: =IF(B196="","",TEXT(YEAR(B196),"0")) -> 2024
A197: MC-24-0196 | B197: 45464 | C197: =IF(B197="","",DATE(YEAR(B197),MONTH(B197),1)) -> 45444 | D197: Jay Ambe Metallizers Pvt. Ltd. | E197: Domestic | F197: Gujarat | G197: MC-10 | H197: Orange R | I197: C.I. Solvent Orange 99 | J197: Orange | K197: Metallised Film & Foil Coating | L197: 25 | M197: 1060 | N197: =IF(L197="","",L197*M197) -> 26500 | O197: 717 | P197: =IF(L197="","",N197-L197*O197) -> 8575 | Q197: 12 | S197: In Production | T197: =IF(R197="","",IF(R197<=Q197,"Yes","No")) | U197: =IF(B197="","",TEXT(YEAR(B197),"0")) -> 2024
A198: MC-24-0197 | B198: 45467 | C198: =IF(B198="","",DATE(YEAR(B198),MONTH(B198),1)) -> 45444 | D198: Krishna Print Inks Pvt. Ltd. | E198: Domestic | F198: Gujarat | G198: MC-26 | H198: Cadbury Violet | I198: - | J198: Blue / Violet | K198: Printing Inks (Flexo / Gravure) | L198: 25 | M198: 1500 | N198: =IF(L198="","",L198*M198) -> 37500 | O198: 941 | P198: =IF(L198="","",N198-L198*O198) -> 13975 | Q198: 10 | S198: In Production | T198: =IF(R198="","",IF(R198<=Q198,"Yes","No")) | U198: =IF(B198="","",TEXT(YEAR(B198),"0")) -> 2024
A199: MC-24-0198 | B199: 45468 | C199: =IF(B199="","",DATE(YEAR(B199),MONTH(B199),1)) -> 45444 | D199: Sri Lakshmi Leather Chemicals | E199: Domestic | F199: Tamil Nadu | G199: MC-05 | H199: Yellow 2R | I199: C.I. Solvent Orange 45 | J199: Yellow | K199: Leather Finishing | L199: 25 | M199: 895 | N199: =IF(L199="","",L199*M199) -> 22375 | O199: 618 | P199: =IF(L199="","",N199-L199*O199) -> 6925 | Q199: 10 | S199: Pending Dispatch | T199: =IF(R199="","",IF(R199<=Q199,"Yes","No")) | U199: =IF(B199="","",TEXT(YEAR(B199),"0")) -> 2024
A200: MC-24-0199 | B200: 45470 | C200: =IF(B200="","",DATE(YEAR(B200),MONTH(B200),1)) -> 45444 | D200: Jay Ambe Metallizers Pvt. Ltd. | E200: Domestic | F200: Gujarat | G200: MC-18 | H200: Pink 5BLG | I200: C.I. Solvent Red 127 | J200: Pink | K200: Hot Foil Stamping | L200: 50 | M200: 1295 | N200: =IF(L200="","",L200*M200) -> 64750 | O200: 879 | P200: =IF(L200="","",N200-L200*O200) -> 20800 | Q200: 15 | S200: In Production | T200: =IF(R200="","",IF(R200<=Q200,"Yes","No")) | U200: =IF(B200="","",TEXT(YEAR(B200),"0")) -> 2024
A201: MC-24-0200 | B201: 45472 | C201: =IF(B201="","",DATE(YEAR(B201),MONTH(B201),1)) -> 45444 | D201: Pioneer Foils & Films Pvt. Ltd. | E201: Domestic | F201: Maharashtra | G201: MC-01 | H201: Yellow 2RLS | I201: C.I. Solvent Yellow 62 | J201: Yellow | K201: Aluminium & Metal Coating | L201: 25 | M201: 910 | N201: =IF(L201="","",L201*M201) -> 22750 | O201: 604 | P201: =IF(L201="","",N201-L201*O201) -> 7650 | Q201: 10 | R201: 11 | S201: Delivered | T201: =IF(R201="","",IF(R201<=Q201,"Yes","No")) -> No | U201: =IF(B201="","",TEXT(YEAR(B201),"0")) -> 2024
C202: =IF(B202="","",DATE(YEAR(B202),MONTH(B202),1)) | N202: =IF(L202="","",L202*M202) | P202: =IF(L202="","",N202-L202*O202) | T202: =IF(R202="","",IF(R202<=Q202,"Yes","No")) | U202: =IF(B202="","",TEXT(YEAR(B202),"0"))
C203: =IF(B203="","",DATE(YEAR(B203),MONTH(B203),1)) | N203: =IF(L203="","",L203*M203) | P203: =IF(L203="","",N203-L203*O203) | T203: =IF(R203="","",IF(R203<=Q203,"Yes","No")) | U203: =IF(B203="","",TEXT(YEAR(B203),"0"))
C204: =IF(B204="","",DATE(YEAR(B204),MONTH(B204),1)) | N204: =IF(L204="","",L204*M204) | P204: =IF(L204="","",N204-L204*O204) | T204: =IF(R204="","",IF(R204<=Q204,"Yes","No")) | U204: =IF(B204="","",TEXT(YEAR(B204),"0"))
C205: =IF(B205="","",DATE(YEAR(B205),MONTH(B205),1)) | N205: =IF(L205="","",L205*M205) | P205: =IF(L205="","",N205-L205*O205) | T205: =IF(R205="","",IF(R205<=Q205,"Yes","No")) | U205: =IF(B205="","",TEXT(YEAR(B205),"0"))
C206: =IF(B206="","",DATE(YEAR(B206),MONTH(B206),1)) | N206: =IF(L206="","",L206*M206) | P206: =IF(L206="","",N206-L206*O206) | T206: =IF(R206="","",IF(R206<=Q206,"Yes","No")) | U206: =IF(B206="","",TEXT(YEAR(B206),"0"))
C207: =IF(B207="","",DATE(YEAR(B207),MONTH(B207),1)) | N207: =IF(L207="","",L207*M207) | P207: =IF(L207="","",N207-L207*O207) | T207: =IF(R207="","",IF(R207<=Q207,"Yes","No")) | U207: =IF(B207="","",TEXT(YEAR(B207),"0"))
C208: =IF(B208="","",DATE(YEAR(B208),MONTH(B208),1)) | N208: =IF(L208="","",L208*M208) | P208: =IF(L208="","",N208-L208*O208) | T208: =IF(R208="","",IF(R208<=Q208,"Yes","No")) | U208: =IF(B208="","",TEXT(YEAR(B208),"0"))
C209: =IF(B209="","",DATE(YEAR(B209),MONTH(B209),1)) | N209: =IF(L209="","",L209*M209) | P209: =IF(L209="","",N209-L209*O209) | T209: =IF(R209="","",IF(R209<=Q209,"Yes","No")) | U209: =IF(B209="","",TEXT(YEAR(B209),"0"))
C210: =IF(B210="","",DATE(YEAR(B210),MONTH(B210),1)) | N210: =IF(L210="","",L210*M210) | P210: =IF(L210="","",N210-L210*O210) | T210: =IF(R210="","",IF(R210<=Q210,"Yes","No")) | U210: =IF(B210="","",TEXT(YEAR(B210),"0"))
C211: =IF(B211="","",DATE(YEAR(B211),MONTH(B211),1)) | N211: =IF(L211="","",L211*M211) | P211: =IF(L211="","",N211-L211*O211) | T211: =IF(R211="","",IF(R211<=Q211,"Yes","No")) | U211: =IF(B211="","",TEXT(YEAR(B211),"0"))
C212: =IF(B212="","",DATE(YEAR(B212),MONTH(B212),1)) | N212: =IF(L212="","",L212*M212) | P212: =IF(L212="","",N212-L212*O212) | T212: =IF(R212="","",IF(R212<=Q212,"Yes","No")) | U212: =IF(B212="","",TEXT(YEAR(B212),"0"))
C213: =IF(B213="","",DATE(YEAR(B213),MONTH(B213),1)) | N213: =IF(L213="","",L213*M213) | P213: =IF(L213="","",N213-L213*O213) | T213: =IF(R213="","",IF(R213<=Q213,"Yes","No")) | U213: =IF(B213="","",TEXT(YEAR(B213),"0"))
... C1500: =IF(B1500="","",DATE(YEAR(B1500),MONTH(B1500),1)) | N1500: =IF(L1500="","",L1500*M1500) | P1500: =IF(L1500="","",N1500-L1500*O1500) | T1500: =IF(R1500="","",IF(R1500<=Q1500,"Yes","No")) | U1500: =IF(B1500="","",TEXT(YEAR(B1500),"0"))

Sheet Product_Master
A1: Product Code | B1: Product (Shade) | C1: C.I. Name | D1: Shade Family | E1: List Price (₹/kg) | F1: Std Cost Ratio | H1: Source: shade card product names & C.I. names (Mansi Solvent Soluble Dyes). Prices, cost ratios and sales data are simulated for illustration.
A2: MC-01 | B2: Yellow 2RLS | C2: C.I. Solvent Yellow 62 | D2: Yellow | E2: 820 | F2: 0.72
A3: MC-02 | B3: Yellow R | C3: C.I. Solvent Yellow 82 | D3: Yellow | E3: 780 | F3: 0.72
A4: MC-03 | B4: Yellow GL | C4: C.I. Solvent Yellow 90 | D4: Yellow | E4: 760 | F4: 0.73
A5: MC-04 | B5: Yellow 4GF | C5: C.I. Solvent Yellow 146 | D5: Yellow | E5: 880 | F5: 0.71
A6: MC-05 | B6: Yellow 2R | C6: C.I. Solvent Orange 45 | D6: Yellow | E6: 840 | F6: 0.72
A7: MC-06 | B7: Golden Yellow | C7: - | D7: Yellow | E7: 800 | F7: 0.72
A8: MC-07 | B8: Orange RE | C8: C.I. Solvent Orange 54 | D8: Orange | E8: 900 | F8: 0.71
A9: MC-08 | B9: Orange RL | C9: C.I. Solvent Orange 58 | D9: Orange | E9: 940 | F9: 0.71
A10: MC-09 | B10: Orange 2R | C10: C.I. Solvent Orange 62 | D10: Orange | E10: 960 | F10: 0.7
A11: MC-10 | B11: Orange R | C11: C.I. Solvent Orange 99 | D11: Orange | E11: 980 | F11: 0.7
A12: MC-11 | B12: Red 2BL | C12: C.I. Solvent Red 132 | D12: Red | E12: 1050 | F12: 0.7
A13: MC-12 | B13: Red BB | C13: C.I. Solvent Red 8 | D13: Red | E13: 1000 | F13: 0.7
... A38: MC-37 | B38: Maroon | C38: - | D38: Red | E38: 980 | F38: 0.71

Sheet Calc
A1: Region filter (criteria) | B1: =IF(Dashboard!$D$4="All","*",Dashboard!$D$4) -> *
A2: Year filter (criteria) | B2: =IF(Dashboard!$H$4="All","*",TEXT(Dashboard!$H$4,"0")) -> *
A3: MONTHLY | L3: YEAR-ON-YEAR BY MONTH (region filter applies; year filter does not)
A4: Month | B4: Revenue (₹ Lakh) | C4: Qty (kg) | D4: Gross Margin (₹ Lakh) | E4: GM % | F4: Forecast Qty (kg) [input] | G4: Orders | H4: Actual Qty - All regions (kg) | I4: Forecast Qty (kg) | J4: Actual Qty (kg) | L4: Month | M4: 2023 | N4: 2024
A5: 44927 | B5: =SUMIFS(Sales_Data!$N$2:$N$1500,Sales_Data!$C$2:$C$1500,$A5,Sales_Data!$E$2:$E$1500,$B$1,Sales_Data!$U$2:$U$1500,$B$2)/100000 -> 8.59625 | C5: =SUMIFS(Sales_Data!$L$2:$L$1500,Sales_Data!$C$2:$C$1500,$A5,Sales_Data!$E$2:$E$1500,$B$1,Sales_Data!$U$2:$U$1500,$B$2) -> 1125 | D5: =SUMIFS(Sales_Data!$P$2:$P$1500,Sales_Data!$C$2:$C$1500,$A5,Sales_Data!$E$2:$E$1500,$B$1,Sales_Data!$U$2:$U$1500,$B$2)/100000 -> 2.07875 | E5: =IF(B5=0,NA(),D5/B5) -> 0.24182056 | F5: 1230 | G5: =COUNTIFS(Sales_Data!$C$2:$C$1500,$A5,Sales_Data!$E$2:$E$1500,$B$1,Sales_Data!$U$2:$U$1500,$B$2) -> 10 | H5: =SUMIFS(Sales_Data!$L$2:$L$1500,Sales_Data!$C$2:$C$1500,$A5) -> 1125 | I5: =IF(OR(Dashboard!$H$4="All",YEAR($A5)=Dashboard!$H$4),F5,NA()) -> 1230 | J5: =IF(OR(Dashboard!$H$4="All",YEAR($A5)=Dashboard!$H$4),H5,NA()) -> 1125 | L5: Jan | M5: =SUMIFS(Sales_Data!$N$2:$N$1500,Sales_Data!$C$2:$C$1500,DATE(2023,1,1),Sales_Data!$E$2:$E$1500,$B$1)/100000 -> 8.59625 | N5: =SUMIFS(Sales_Data!$N$2:$N$1500,Sales_Data!$C$2:$C$1500,DATE(2024,1,1),Sales_Data!$E$2:$E$1500,$B$1)/100000 -> 15.8225
A6: 44958 | B6: =SUMIFS(Sales_Data!$N$2:$N$1500,Sales_Data!$C$2:$C$1500,$A6,Sales_Data!$E$2:$E$1500,$B$1,Sales_Data!$U$2:$U$1500,$B$2)/100000 -> 14.42 | C6: =SUMIFS(Sales_Data!$L$2:$L$1500,Sales_Data!$C$2:$C$1500,$A6,Sales_Data!$E$2:$E$1500,$B$1,Sales_Data!$U$2:$U$1500,$B$2) -> 1750 | D6: =SUMIFS(Sales_Data!$P$2:$P$1500,Sales_Data!$C$2:$C$1500,$A6,Sales_Data!$E$2:$E$1500,$B$1,Sales_Data!$U$2:$U$1500,$B$2)/100000 -> 3.6025 | E6: =IF(B6=0,NA(),D6/B6) -> 0.24982663 | F6: 1890 | G6: =COUNTIFS(Sales_Data!$C$2:$C$1500,$A6,Sales_Data!$E$2:$E$1500,$B$1,Sales_Data!$U$2:$U$1500,$B$2) -> 13 | H6: =SUMIFS(Sales_Data!$L$2:$L$1500,Sales_Data!$C$2:$C$1500,$A6) -> 1750 | I6: =IF(OR(Dashboard!$H$4="All",YEAR($A6)=Dashboard!$H$4),F6,NA()) -> 1890 | J6: =IF(OR(Dashboard!$H$4="All",YEAR($A6)=Dashboard!$H$4),H6,NA()) -> 1750 | L6: Feb | M6: =SUMIFS(Sales_Data!$N$2:$N$1500,Sales_Data!$C$2:$C$1500,DATE(2023,2,1),Sales_Data!$E$2:$E$1500,$B$1)/100000 -> 14.42 | N6: =SUMIFS(Sales_Data!$N$2:$N$1500,Sales_Data!$C$2:$C$1500,DATE(2024,2,1),Sales_Data!$E$2:$E$1500,$B$1)/100000 -> 13.4825
A7: 44986 | B7: =SUMIFS(Sales_Data!$N$2:$N$1500,Sales_Data!$C$2:$C$1500,$A7,Sales_Data!$E$2:$E$1500,$B$1,Sales_Data!$U$2:$U$1500,$B$2)/100000 -> 13.94625 | C7: =SUMIFS(Sales_Data!$L$2:$L$1500,Sales_Data!$C$2:$C$1500,$A7,Sales_Data!$E$2:$E$1500,$B$1,Sales_Data!$U$2:$U$1500,$B$2) -> 1875 | D7: =SUMIFS(Sales_Data!$P$2:$P$1500,Sales_Data!$C$2:$C$1500,$A7,Sales_Data!$E$2:$E$1500,$B$1,Sales_Data!$U$2:$U$1500,$B$2)/100000 -> 3.25725 | E7: =IF(B7=0,NA(),D7/B7) -> 0.23355741 | F7: 1790 | G7: =COUNTIFS(Sales_Data!$C$2:$C$1500,$A7,Sales_Data!$E$2:$E$1500,$B$1,Sales_Data!$U$2:$U$1500,$B$2) -> 13 | H7: =SUMIFS(Sales_Data!$L$2:$L$1500,Sales_Data!$C$2:$C$1500,$A7) -> 1875 | I7: =IF(OR(Dashboard!$H$4="All",YEAR($A7)=Dashboard!$H$4),F7,NA()) -> 1790 | J7: =IF(OR(Dashboard!$H$4="All",YEAR($A7)=Dashboard!$H$4),H7,NA()) -> 1875 | L7: Mar | M7: =SUMIFS(Sales_Data!$N$2:$N$1500,Sales_Data!$C$2:$C$1500,DATE(2023,3,1),Sales_Data!$E$2:$E$1500,$B$1)/100000 -> 13.94625 | N7: =SUMIFS(Sales_Data!$N$2:$N$1500,Sales_Data!$C$2:$C$1500,DATE(2024,3,1),Sales_Data!$E$2:$E$1500,$B$1)/100000 -> 15.82625
A8: 45017 | B8: =SUMIFS(Sales_Data!$N$2:$N$1500,Sales_Data!$C$2:$C$1500,$A8,Sales_Data!$E$2:$E$1500,$B$1,Sales_Data!$U$2:$U$1500,$B$2)/100000 -> 6.72 | C8: =SUMIFS(Sales_Data!$L$2:$L$1500,Sales_Data!$C$2:$C$1500,$A8,Sales_Data!$E$2:$E$1500,$B$1,Sales_Data!$U$2:$U$1500,$B$2) -> 700 | D8: =SUMIFS(Sales_Data!$P$2:$P$1500,Sales_Data!$C$2:$C$1500,$A8,Sales_Data!$E$2:$E$1500,$B$1,Sales_Data!$U$2:$U$1500,$B$2)/100000 -> 1.951 | E8: =IF(B8=0,NA(),D8/B8) -> 0.29032738 | F8: 710 | G8: =COUNTIFS(Sales_Data!$C$2:$C$1500,$A8,Sales_Data!$E$2:$E$1500,$B$1,Sales_Data!$U$2:$U$1500,$B$2) -> 9 | H8: =SUMIFS(Sales_Data!$L$2:$L$1500,Sales_Data!$C$2:$C$1500,$A8) -> 700 | I8: =IF(OR(Dashboard!$H$4="All",YEAR($A8)=Dashboard!$H$4),F8,NA()) -> 710 | J8: =IF(OR(Dashboard!$H$4="All",YEAR($A8)=Dashboard!$H$4),H8,NA()) -> 700 | L8: Apr | M8: =SUMIFS(Sales_Data!$N$2:$N$1500,Sales_Data!$C$2:$C$1500,DATE(2023,4,1),Sales_Data!$E$2:$E$1500,$B$1)/100000 -> 6.72 | N8: =SUMIFS(Sales_Data!$N$2:$N$1500,Sales_Data!$C$2:$C$1500,DATE(2024,4,1),Sales_Data!$E$2:$E$1500,$B$1)/100000 -> 14.6875
A9: 45047 | B9: =SUMIFS(Sales_Data!$N$2:$N$1500,Sales_Data!$C$2:$C$1500,$A9,Sales_Data!$E$2:$E$1500,$B$1,Sales_Data!$U$2:$U$1500,$B$2)/100000 -> 9.80625 | C9: =SUMIFS(Sales_Data!$L$2:$L$1500,Sales_Data!$C$2:$C$1500,$A9,Sales_Data!$E$2:$E$1500,$B$1,Sales_Data!$U$2:$U$1500,$B$2) -> 1300 | D9: =SUMIFS(Sales_Data!$P$2:$P$1500,Sales_Data!$C$2:$C$1500,$A9,Sales_Data!$E$2:$E$1500,$B$1,Sales_Data!$U$2:$U$1500,$B$2)/100000 -> 2.30575 | E9: =IF(B9=0,NA(),D9/B9) -> 0.23513066 | F9: 1320 | G9: =COUNTIFS(Sales_Data!$C$2:$C$1500,$A9,Sales_Data!$E$2:$E$1500,$B$1,Sales_Data!$U$2:$U$1500,$B$2) -> 10 | H9: =SUMIFS(Sales_Data!$L$2:$L$1500,Sales_Data!$C$2:$C$1500,$A9) -> 1300 | I9: =IF(OR(Dashboard!$H$4="All",YEAR($A9)=Dashboard!$H$4),F9,NA()) -> 1320 | J9: =IF(OR(Dashboard!$H$4="All",YEAR($A9)=Dashboard!$H$4),H9,NA()) -> 1300 | L9: May | M9: =SUMIFS(Sales_Data!$N$2:$N$1500,Sales_Data!$C$2:$C$1500,DATE(2023,5,1),Sales_Data!$E$2:$E$1500,$B$1)/100000 -> 9.80625 | N9: =SUMIFS(Sales_Data!$N$2:$N$1500,Sales_Data!$C$2:$C$1500,DATE(2024,5,1),Sales_Data!$E$2:$E$1500,$B$1)/100000 -> 8.86
A10: 45078 | B10: =SUMIFS(Sales_Data!$N$2:$N$1500,Sales_Data!$C$2:$C$1500,$A10,Sales_Data!$E$2:$E$1500,$B$1,Sales_Data!$U$2:$U$1500,$B$2)/100000 -> 13.135 | C10: =SUMIFS(Sales_Data!$L$2:$L$1500,Sales_Data!$C$2:$C$1500,$A10,Sales_Data!$E$2:$E$1500,$B$1,Sales_Data!$U$2:$U$1500,$B$2) -> 1400 | D10: =SUMIFS(Sales_Data!$P$2:$P$1500,Sales_Data!$C$2:$C$1500,$A10,Sales_Data!$E$2:$E$1500,$B$1,Sales_Data!$U$2:$U$1500,$B$2)/100000 -> 3.408 | E10: =IF(B10=0,NA(),D10/B10) -> 0.25945946 | F10: 1280 | G10: =COUNTIFS(Sales_Data!$C$2:$C$1500,$A10,Sales_Data!$E$2:$E$1500,$B$1,Sales_Data!$U$2:$U$1500,$B$2) -> 9 | H10: =SUMIFS(Sales_Data!$L$2:$L$1500,Sales_Data!$C$2:$C$1500,$A10) -> 1400 | I10: =IF(OR(Dashboard!$H$4="All",YEAR($A10)=Dashboard!$H$4),F10,NA()) -> 1280 | J10: =IF(OR(Dashboard!$H$4="All",YEAR($A10)=Dashboard!$H$4),H10,NA()) -> 1400 | L10: Jun | M10: =SUMIFS(Sales_Data!$N$2:$N$1500,Sales_Data!$C$2:$C$1500,DATE(2023,6,1),Sales_Data!$E$2:$E$1500,$B$1)/100000 -> 13.135 | N10: =SUMIFS(Sales_Data!$N$2:$N$1500,Sales_Data!$C$2:$C$1500,DATE(2024,6,1),Sales_Data!$E$2:$E$1500,$B$1)/100000 -> 6.2625
A11: 45108 | B11: =SUMIFS(Sales_Data!$N$2:$N$1500,Sales_Data!$C$2:$C$1500,$A11,Sales_Data!$E$2:$E$1500,$B$1,Sales_Data!$U$2:$U$1500,$B$2)/100000 -> 6.715 | C11: =SUMIFS(Sales_Data!$L$2:$L$1500,Sales_Data!$C$2:$C$1500,$A11,Sales_Data!$E$2:$E$1500,$B$1,Sales_Data!$U$2:$U$1500,$B$2) -> 650 | D11: =SUMIFS(Sales_Data!$P$2:$P$1500,Sales_Data!$C$2:$C$1500,$A11,Sales_Data!$E$2:$E$1500,$B$1,Sales_Data!$U$2:$U$1500,$B$2)/100000 -> 2.0015 | E11: =IF(B11=0,NA(),D11/B11) -> 0.29806404 | F11: 640 | G11: =COUNTIFS(Sales_Data!$C$2:$C$1500,$A11,Sales_Data!$E$2:$E$1500,$B$1,Sales_Data!$U$2:$U$1500,$B$2) -> 8 | H11: =SUMIFS(Sales_Data!$L$2:$L$1500,Sales_Data!$C$2:$C$1500,$A11) -> 650 | I11: =IF(OR(Dashboard!$H$4="All",YEAR($A11)=Dashboard!$H$4),F11,NA()) -> 640 | J11: =IF(OR(Dashboard!$H$4="All",YEAR($A11)=Dashboard!$H$4),H11,NA()) -> 650 | L11: Jul | M11: =SUMIFS(Sales_Data!$N$2:$N$1500,Sales_Data!$C$2:$C$1500,DATE(2023,7,1),Sales_Data!$E$2:$E$1500,$B$1)/100000 -> 6.715 | N11: =SUMIFS(Sales_Data!$N$2:$N$1500,Sales_Data!$C$2:$C$1500,DATE(2024,7,1),Sales_Data!$E$2:$E$1500,$B$1)/100000 -> 0
A12: 45139 | B12: =SUMIFS(Sales_Data!$N$2:$N$1500,Sales_Data!$C$2:$C$1500,$A12,Sales_Data!$E$2:$E$1500,$B$1,Sales_Data!$U$2:$U$1500,$B$2)/100000 -> 8.5925 | C12: =SUMIFS(Sales_Data!$L$2:$L$1500,Sales_Data!$C$2:$C$1500,$A12,Sales_Data!$E$2:$E$1500,$B$1,Sales_Data!$U$2:$U$1500,$B$2) -> 1050 | D12: =SUMIFS(Sales_Data!$P$2:$P$1500,Sales_Data!$C$2:$C$1500,$A12,Sales_Data!$E$2:$E$1500,$B$1,Sales_Data!$U$2:$U$1500,$B$2)/100000 -> 2.261 | E12: =IF(B12=0,NA(),D12/B12) -> 0.26313646 | F12: 1000 | G12: =COUNTIFS(Sales_Data!$C$2:$C$1500,$A12,Sales_Data!$E$2:$E$1500,$B$1,Sales_Data!$U$2:$U$1500,$B$2) -> 9 | H12: =SUMIFS(Sales_Data!$L$2:$L$1500,Sales_Data!$C$2:$C$1500,$A12) -> 1050 | I12: =IF(OR(Dashboard!$H$4="All",YEAR($A12)=Dashboard!$H$4),F12,NA()) -> 1000 | J12: =IF(OR(Dashboard!$H$4="All",YEAR($A12)=Dashboard!$H$4),H12,NA()) -> 1050 | L12: Aug | M12: =SUMIFS(Sales_Data!$N$2:$N$1500,Sales_Data!$C$2:$C$1500,DATE(2023,8,1),Sales_Data!$E$2:$E$1500,$B$1)/100000 -> 8.5925 | N12: =SUMIFS(Sales_Data!$N$2:$N$1500,Sales_Data!$C$2:$C$1500,DATE(2024,8,1),Sales_Data!$E$2:$E$1500,$B$1)/100000 -> 0
A13: 45170 | B13: =SUMIFS(Sales_Data!$N$2:$N$1500,Sales_Data!$C$2:$C$1500,$A13,Sales_Data!$E$2:$E$1500,$B$1,Sales_Data!$U$2:$U$1500,$B$2)/100000 -> 14.37375 | C13: =SUMIFS(Sales_Data!$L$2:$L$1500,Sales_Data!$C$2:$C$1500,$A13,Sales_Data!$E$2:$E$1500,$B$1,Sales_Data!$U$2:$U$1500,$B$2) -> 1475 | D13: =SUMIFS(Sales_Data!$P$2:$P$1500,Sales_Data!$C$2:$C$1500,$A13,Sales_Data!$E$2:$E$1500,$B$1,Sales_Data!$U$2:$U$1500,$B$2)/100000 -> 4.14125 | E13: =IF(B13=0,NA(),D13/B13) -> 0.28811201 | F13: 1580 | G13: =COUNTIFS(Sales_Data!$C$2:$C$1500,$A13,Sales_Data!$E$2:$E$1500,$B$1,Sales_Data!$U$2:$U$1500,$B$2) -> 10 | H13: =SUMIFS(Sales_Data!$L$2:$L$1500,Sales_Data!$C$2:$C$1500,$A13) -> 1475 | I13: =IF(OR(Dashboard!$H$4="All",YEAR($A13)=Dashboard!$H$4),F13,NA()) -> 1580 | J13: =IF(OR(Dashboard!$H$4="All",YEAR($A13)=Dashboard!$H$4),H13,NA()) -> 1475 | L13: Sep | M13: =SUMIFS(Sales_Data!$N$2:$N$1500,Sales_Data!$C$2:$C$1500,DATE(2023,9,1),Sales_Data!$E$2:$E$1500,$B$1)/100000 -> 14.37375 | N13: =SUMIFS(Sales_Data!$N$2:$N$1500,Sales_Data!$C$2:$C$1500,DATE(2024,9,1),Sales_Data!$E$2:$E$1500,$B$1)/100000 -> 0
A14: 45200 | B14: =SUMIFS(Sales_Data!$N$2:$N$1500,Sales_Data!$C$2:$C$1500,$A14,Sales_Data!$E$2:$E$1500,$B$1,Sales_Data!$U$2:$U$1500,$B$2)/100000 -> 21.97875 | C14: =SUMIFS(Sales_Data!$L$2:$L$1500,Sales_Data!$C$2:$C$1500,$A14,Sales_Data!$E$2:$E$1500,$B$1,Sales_Data!$U$2:$U$1500,$B$2) -> 2150 | D14: =SUMIFS(Sales_Data!$P$2:$P$1500,Sales_Data!$C$2:$C$1500,$A14,Sales_Data!$E$2:$E$1500,$B$1,Sales_Data!$U$2:$U$1500,$B$2)/100000 -> 6.07875 | E14: =IF(B14=0,NA(),D14/B14) -> 0.27657396 | F14: 2060 | G14: =COUNTIFS(Sales_Data!$C$2:$C$1500,$A14,Sales_Data!$E$2:$E$1500,$B$1,Sales_Data!$U$2:$U$1500,$B$2) -> 13 | H14: =SUMIFS(Sales_Data!$L$2:$L$1500,Sales_Data!$C$2:$C$1500,$A14) -> 2150 | I14: =IF(OR(Dashboard!$H$4="All",YEAR($A14)=Dashboard!$H$4),F14,NA()) -> 2060 | J14: =IF(OR(Dashboard!$H$4="All",YEAR($A14)=Dashboard!$H$4),H14,NA()) -> 2150 | L14: Oct | M14: =SUMIFS(Sales_Data!$N$2:$N$1500,Sales_Data!$C$2:$C$1500,DATE(2023,10,1),Sales_Data!$E$2:$E$1500,$B$1)/100000 -> 21.97875 | N14: =SUMIFS(Sales_Data!$N$2:$N$1500,Sales_Data!$C$2:$C$1500,DATE(2024,10,1),Sales_Data!$E$2:$E$1500,$B$1)/100000 -> 0
A15: 45231 | B15: =SUMIFS(Sales_Data!$N$2:$N$1500,Sales_Data!$C$2:$C$1500,$A15,Sales_Data!$E$2:$E$1500,$B$1,Sales_Data!$U$2:$U$1500,$B$2)/100000 -> 18.32375 | C15: =SUMIFS(Sales_Data!$L$2:$L$1500,Sales_Data!$C$2:$C$1500,$A15,Sales_Data!$E$2:$E$1500,$B$1,Sales_Data!$U$2:$U$1500,$B$2) -> 1875 | D15: =SUMIFS(Sales_Data!$P$2:$P$1500,Sales_Data!$C$2:$C$1500,$A15,Sales_Data!$E$2:$E$1500,$B$1,Sales_Data!$U$2:$U$1500,$B$2)/100000 -> 5.169 | E15: =IF(B15=0,NA(),D15/B15) -> 0.28209291 | F15: 1730 | G15: =COUNTIFS(Sales_Data!$C$2:$C$1500,$A15,Sales_Data!$E$2:$E$1500,$B$1,Sales_Data!$U$2:$U$1500,$B$2) -> 14 | H15: =SUMIFS(Sales_Data!$L$2:$L$1500,Sales_Data!$C$2:$C$1500,$A15) -> 1875 | I15: =IF(OR(Dashboard!$H$4="All",YEAR($A15)=Dashboard!$H$4),F15,NA()) -> 1730 | J15: =IF(OR(Dashboard!$H$4="All",YEAR($A15)=Dashboard!$H$4),H15,NA()) -> 1875 | L15: Nov | M15: =SUMIFS(Sales_Data!$N$2:$N$1500,Sales_Data!$C$2:$C$1500,DATE(2023,11,1),Sales_Data!$E$2:$E$1500,$B$1)/100000 -> 18.32375 | N15: =SUMIFS(Sales_Data!$N$2:$N$1500,Sales_Data!$C$2:$C$1500,DATE(2024,11,1),Sales_Data!$E$2:$E$1500,$B$1)/100000 -> 0
A16: 45261 | B16: =SUMIFS(Sales_Data!$N$2:$N$1500,Sales_Data!$C$2:$C$1500,$A16,Sales_Data!$E$2:$E$1500,$B$1,Sales_Data!$U$2:$U$1500,$B$2)/100000 -> 8.795 | C16: =SUMIFS(Sales_Data!$L$2:$L$1500,Sales_Data!$C$2:$C$1500,$A16,Sales_Data!$E$2:$E$1500,$B$1,Sales_Data!$U$2:$U$1500,$B$2) -> 950 | D16: =SUMIFS(Sales_Data!$P$2:$P$1500,Sales_Data!$C$2:$C$1500,$A16,Sales_Data!$E$2:$E$1500,$B$1,Sales_Data!$U$2:$U$1500,$B$2)/100000 -> 2.4575 | E16: =IF(B16=0,NA(),D16/B16) -> 0.27942013 | F16: 1040 | G16: =COUNTIFS(Sales_Data!$C$2:$C$1500,$A16,Sales_Data!$E$2:$E$1500,$B$1,Sales_Data!$U$2:$U$1500,$B$2) -> 13 | H16: =SUMIFS(Sales_Data!$L$2:$L$1500,Sales_Data!$C$2:$C$1500,$A16) -> 950 | I16: =IF(OR(Dashboard!$H$4="All",YEAR($A16)=Dashboard!$H$4),F16,NA()) -> 1040 | J16: =IF(OR(Dashboard!$H$4="All",YEAR($A16)=Dashboard!$H$4),H16,NA()) -> 950 | L16: Dec | M16: =SUMIFS(Sales_Data!$N$2:$N$1500,Sales_Data!$C$2:$C$1500,DATE(2023,12,1),Sales_Data!$E$2:$E$1500,$B$1)/100000 -> 8.795 | N16: =SUMIFS(Sales_Data!$N$2:$N$1500,Sales_Data!$C$2:$C$1500,DATE(2024,12,1),Sales_Data!$E$2:$E$1500,$B$1)/100000 -> 0
A17: 45292 | B17: =SUMIFS(Sales_Data!$N$2:$N$1500,Sales_Data!$C$2:$C$1500,$A17,Sales_Data!$E$2:$E$1500,$B$1,Sales_Data!$U$2:$U$1500,$B$2)/100000 -> 15.8225 | C17: =SUMIFS(Sales_Data!$L$2:$L$1500,Sales_Data!$C$2:$C$1500,$A17,Sales_Data!$E$2:$E$1500,$B$1,Sales_Data!$U$2:$U$1500,$B$2) -> 1525 | D17: =SUMIFS(Sales_Data!$P$2:$P$1500,Sales_Data!$C$2:$C$1500,$A17,Sales_Data!$E$2:$E$1500,$B$1,Sales_Data!$U$2:$U$1500,$B$2)/100000 -> 4.547 | E17: =IF(B17=0,NA(),D17/B17) -> 0.28737557 | F17: 1690 | G17: =COUNTIFS(Sales_Data!$C$2:$C$1500,$A17,Sales_Data!$E$2:$E$1500,$B$1,Sales_Data!$U$2:$U$1500,$B$2) -> 13 | H17: =SUMIFS(Sales_Data!$L$2:$L$1500,Sales_Data!$C$2:$C$1500,$A17) -> 1525 | I17: =IF(OR(Dashboard!$H$4="All",YEAR($A17)=Dashboard!$H$4),F17,NA()) -> 1690 | J17: =IF(OR(Dashboard!$H$4="All",YEAR($A17)=Dashboard!$H$4),H17,NA()) -> 1525
A18: 45323 | B18: =SUMIFS(Sales_Data!$N$2:$N$1500,Sales_Data!$C$2:$C$1500,$A18,Sales_Data!$E$2:$E$1500,$B$1,Sales_Data!$U$2:$U$1500,$B$2)/100000 -> 13.4825 | C18: =SUMIFS(Sales_Data!$L$2:$L$1500,Sales_Data!$C$2:$C$1500,$A18,Sales_Data!$E$2:$E$1500,$B$1,Sales_Data!$U$2:$U$1500,$B$2) -> 1550 | D18: =SUMIFS(Sales_Data!$P$2:$P$1500,Sales_Data!$C$2:$C$1500,$A18,Sales_Data!$E$2:$E$1500,$B$1,Sales_Data!$U$2:$U$1500,$B$2)/100000 -> 3.668 | E18: =IF(B18=0,NA(),D18/B18) -> 0.27205637 | F18: 1680 | G18: =COUNTIFS(Sales_Data!$C$2:$C$1500,$A18,Sales_Data!$E$2:$E$1500,$B$1,Sales_Data!$U$2:$U$1500,$B$2) -> 12 | H18: =SUMIFS(Sales_Data!$L$2:$L$1500,Sales_Data!$C$2:$C$1500,$A18) -> 1550 | I18: =IF(OR(Dashboard!$H$4="All",YEAR($A18)=Dashboard!$H$4),F18,NA()) -> 1680 | J18: =IF(OR(Dashboard!$H$4="All",YEAR($A18)=Dashboard!$H$4),H18,NA()) -> 1550
A19: 45352 | B19: =SUMIFS(Sales_Data!$N$2:$N$1500,Sales_Data!$C$2:$C$1500,$A19,Sales_Data!$E$2:$E$1500,$B$1,Sales_Data!$U$2:$U$1500,$B$2)/100000 -> 15.82625 | C19: =SUMIFS(Sales_Data!$L$2:$L$1500,Sales_Data!$C$2:$C$1500,$A19,Sales_Data!$E$2:$E$1500,$B$1,Sales_Data!$U$2:$U$1500,$B$2) -> 1475 | D19: =SUMIFS(Sales_Data!$P$2:$P$1500,Sales_Data!$C$2:$C$1500,$A19,Sales_Data!$E$2:$E$1500,$B$1,Sales_Data!$U$2:$U$1500,$B$2)/100000 -> 4.5165 | E19: =IF(B19=0,NA(),D19/B19) -> 0.2853803 | F19: 1360 | G19: =COUNTIFS(Sales_Data!$C$2:$C$1500,$A19,Sales_Data!$E$2:$E$1500,$B$1,Sales_Data!$U$2:$U$1500,$B$2) -> 15 | H19: =SUMIFS(Sales_Data!$L$2:$L$1500,Sales_Data!$C$2:$C$1500,$A19) -> 1475 | I19: =IF(OR(Dashboard!$H$4="All",YEAR($A19)=Dashboard!$H$4),F19,NA()) -> 1360 | J19: =IF(OR(Dashboard!$H$4="All",YEAR($A19)=Dashboard!$H$4),H19,NA()) -> 1475
A20: 45383 | B20: =SUMIFS(Sales_Data!$N$2:$N$1500,Sales_Data!$C$2:$C$1500,$A20,Sales_Data!$E$2:$E$1500,$B$1,Sales_Data!$U$2:$U$1500,$B$2)/100000 -> 14.6875 | C20: =SUMIFS(Sales_Data!$L$2:$L$1500,Sales_Data!$C$2:$C$1500,$A20,Sales_Data!$E$2:$E$1500,$B$1,Sales_Data!$U$2:$U$1500,$B$2) -> 1500 | D20: =SUMIFS(Sales_Data!$P$2:$P$1500,Sales_Data!$C$2:$C$1500,$A20,Sales_Data!$E$2:$E$1500,$B$1,Sales_Data!$U$2:$U$1500,$B$2)/100000 -> 4.2925 | E20: =IF(B20=0,NA(),D20/B20) -> 0.29225532 | F20: 1410 | G20: =COUNTIFS(Sales_Data!$C$2:$C$1500,$A20,Sales_Data!$E$2:$E$1500,$B$1,Sales_Data!$U$2:$U$1500,$B$2) -> 10 | H20: =SUMIFS(Sales_Data!$L$2:$L$1500,Sales_Data!$C$2:$C$1500,$A20) -> 1500 | I20: =IF(OR(Dashboard!$H$4="All",YEAR($A20)=Dashboard!$H$4),F20,NA()) -> 1410 | J20: =IF(OR(Dashboard!$H$4="All",YEAR($A20)=Dashboard!$H$4),H20,NA()) -> 1500
A21: 45413 | B21: =SUMIFS(Sales_Data!$N$2:$N$1500,Sales_Data!$C$2:$C$1500,$A21,Sales_Data!$E$2:$E$1500,$B$1,Sales_Data!$U$2:$U$1500,$B$2)/100000 -> 8.86 | C21: =SUMIFS(Sales_Data!$L$2:$L$1500,Sales_Data!$C$2:$C$1500,$A21,Sales_Data!$E$2:$E$1500,$B$1,Sales_Data!$U$2:$U$1500,$B$2) -> 950 | D21: =SUMIFS(Sales_Data!$P$2:$P$1500,Sales_Data!$C$2:$C$1500,$A21,Sales_Data!$E$2:$E$1500,$B$1,Sales_Data!$U$2:$U$1500,$B$2)/100000 -> 2.52 | E21: =IF(B21=0,NA(),D21/B21) -> 0.28442438 | F21: 850 | G21: =COUNTIFS(Sales_Data!$C$2:$C$1500,$A21,Sales_Data!$E$2:$E$1500,$B$1,Sales_Data!$U$2:$U$1500,$B$2) -> 9 | H21: =SUMIFS(Sales_Data!$L$2:$L$1500,Sales_Data!$C$2:$C$1500,$A21) -> 950 | I21: =IF(OR(Dashboard!$H$4="All",YEAR($A21)=Dashboard!$H$4),F21,NA()) -> 850 | J21: =IF(OR(Dashboard!$H$4="All",YEAR($A21)=Dashboard!$H$4),H21,NA()) -> 950 | L21: JAN–JUN BY SHADE FAMILY (like-for-like)
A22: 45444 | B22: =SUMIFS(Sales_Data!$N$2:$N$1500,Sales_Data!$C$2:$C$1500,$A22,Sales_Data!$E$2:$E$1500,$B$1,Sales_Data!$U$2:$U$1500,$B$2)/100000 -> 6.2625 | C22: =SUMIFS(Sales_Data!$L$2:$L$1500,Sales_Data!$C$2:$C$1500,$A22,Sales_Data!$E$2:$E$1500,$B$1,Sales_Data!$U$2:$U$1500,$B$2) -> 675 | D22: =SUMIFS(Sales_Data!$P$2:$P$1500,Sales_Data!$C$2:$C$1500,$A22,Sales_Data!$E$2:$E$1500,$B$1,Sales_Data!$U$2:$U$1500,$B$2)/100000 -> 1.84225 | E22: =IF(B22=0,NA(),D22/B22) -> 0.29417166 | F22: 650 | G22: =COUNTIFS(Sales_Data!$C$2:$C$1500,$A22,Sales_Data!$E$2:$E$1500,$B$1,Sales_Data!$U$2:$U$1500,$B$2) -> 10 | H22: =SUMIFS(Sales_Data!$L$2:$L$1500,Sales_Data!$C$2:$C$1500,$A22) -> 675 | I22: =IF(OR(Dashboard!$H$4="All",YEAR($A22)=Dashboard!$H$4),F22,NA()) -> 650 | J22: =IF(OR(Dashboard!$H$4="All",YEAR($A22)=Dashboard!$H$4),H22,NA()) -> 675 | L22: Shade Family | M22: 2023 | N22: 2024
L23: Yellow | M23: =SUMIFS(Sales_Data!$N$2:$N$1500,Sales_Data!$J$2:$J$1500,$L23,Sales_Data!$C$2:$C$1500,">="&DATE(2023,1,1),Sales_Data!$C$2:$C$1500,"<="&DATE(2023,6,1),Sales_Data!$E$2:$E$1500,$B$1)/100000 -> 20.64375 | N23: =SUMIFS(Sales_Data!$N$2:$N$1500,Sales_Data!$J$2:$J$1500,$L23,Sales_Data!$C$2:$C$1500,">="&DATE(2024,1,1),Sales_Data!$C$2:$C$1500,"<="&DATE(2024,6,1),Sales_Data!$E$2:$E$1500,$B$1)/100000 -> 10.40875
L24: Orange | M24: =SUMIFS(Sales_Data!$N$2:$N$1500,Sales_Data!$J$2:$J$1500,$L24,Sales_Data!$C$2:$C$1500,">="&DATE(2023,1,1),Sales_Data!$C$2:$C$1500,"<="&DATE(2023,6,1),Sales_Data!$E$2:$E$1500,$B$1)/100000 -> 1.375 | N24: =SUMIFS(Sales_Data!$N$2:$N$1500,Sales_Data!$J$2:$J$1500,$L24,Sales_Data!$C$2:$C$1500,">="&DATE(2024,1,1),Sales_Data!$C$2:$C$1500,"<="&DATE(2024,6,1),Sales_Data!$E$2:$E$1500,$B$1)/100000 -> 9.9375
L25: Red | M25: =SUMIFS(Sales_Data!$N$2:$N$1500,Sales_Data!$J$2:$J$1500,$L25,Sales_Data!$C$2:$C$1500,">="&DATE(2023,1,1),Sales_Data!$C$2:$C$1500,"<="&DATE(2023,6,1),Sales_Data!$E$2:$E$1500,$B$1)/100000 -> 9.29 | N25: =SUMIFS(Sales_Data!$N$2:$N$1500,Sales_Data!$J$2:$J$1500,$L25,Sales_Data!$C$2:$C$1500,">="&DATE(2024,1,1),Sales_Data!$C$2:$C$1500,"<="&DATE(2024,6,1),Sales_Data!$E$2:$E$1500,$B$1)/100000 -> 11.64875
A26: SHADE FAMILY | L26: Pink | M26: =SUMIFS(Sales_Data!$N$2:$N$1500,Sales_Data!$J$2:$J$1500,$L26,Sales_Data!$C$2:$C$1500,">="&DATE(2023,1,1),Sales_Data!$C$2:$C$1500,"<="&DATE(2023,6,1),Sales_Data!$E$2:$E$1500,$B$1)/100000 -> 0 | N26: =SUMIFS(Sales_Data!$N$2:$N$1500,Sales_Data!$J$2:$J$1500,$L26,Sales_Data!$C$2:$C$1500,">="&DATE(2024,1,1),Sales_Data!$C$2:$C$1500,"<="&DATE(2024,6,1),Sales_Data!$E$2:$E$1500,$B$1)/100000 -> 0.6475
A27: Shade Family | B27: Revenue (₹ Lakh) | C27: Qty (kg) | D27: GM % | L27: Black | M27: =SUMIFS(Sales_Data!$N$2:$N$1500,Sales_Data!$J$2:$J$1500,$L27,Sales_Data!$C$2:$C$1500,">="&DATE(2023,1,1),Sales_Data!$C$2:$C$1500,"<="&DATE(2023,6,1),Sales_Data!$E$2:$E$1500,$B$1)/100000 -> 16.01 | N27: =SUMIFS(Sales_Data!$N$2:$N$1500,Sales_Data!$J$2:$J$1500,$L27,Sales_Data!$C$2:$C$1500,">="&DATE(2024,1,1),Sales_Data!$C$2:$C$1500,"<="&DATE(2024,6,1),Sales_Data!$E$2:$E$1500,$B$1)/100000 -> 11.665
A28: Yellow | B28: =SUMIFS(Sales_Data!$N$2:$N$1500,Sales_Data!$J$2:$J$1500,$A28,Sales_Data!$E$2:$E$1500,$B$1,Sales_Data!$U$2:$U$1500,$B$2)/100000 -> 43.83875 | C28: =SUMIFS(Sales_Data!$L$2:$L$1500,Sales_Data!$J$2:$J$1500,$A28,Sales_Data!$E$2:$E$1500,$B$1,Sales_Data!$U$2:$U$1500,$B$2) -> 5450 | D28: =IF(B28=0,0,SUMIFS(Sales_Data!$P$2:$P$1500,Sales_Data!$J$2:$J$1500,$A28,Sales_Data!$E$2:$E$1500,$B$1,Sales_Data!$U$2:$U$1500,$B$2)/100000/B28) -> 0.26094494 | L28: Blue / Violet | M28: =SUMIFS(Sales_Data!$N$2:$N$1500,Sales_Data!$J$2:$J$1500,$L28,Sales_Data!$C$2:$C$1500,">="&DATE(2023,1,1),Sales_Data!$C$2:$C$1500,"<="&DATE(2023,6,1),Sales_Data!$E$2:$E$1500,$B$1)/100000 -> 6.41125 | N28: =SUMIFS(Sales_Data!$N$2:$N$1500,Sales_Data!$J$2:$J$1500,$L28,Sales_Data!$C$2:$C$1500,">="&DATE(2024,1,1),Sales_Data!$C$2:$C$1500,"<="&DATE(2024,6,1),Sales_Data!$E$2:$E$1500,$B$1)/100000 -> 19.94125
A29: Orange | B29: =SUMIFS(Sales_Data!$N$2:$N$1500,Sales_Data!$J$2:$J$1500,$A29,Sales_Data!$E$2:$E$1500,$B$1,Sales_Data!$U$2:$U$1500,$B$2)/100000 -> 23.3275 | C29: =SUMIFS(Sales_Data!$L$2:$L$1500,Sales_Data!$J$2:$J$1500,$A29,Sales_Data!$E$2:$E$1500,$B$1,Sales_Data!$U$2:$U$1500,$B$2) -> 2450 | D29: =IF(B29=0,0,SUMIFS(Sales_Data!$P$2:$P$1500,Sales_Data!$J$2:$J$1500,$A29,Sales_Data!$E$2:$E$1500,$B$1,Sales_Data!$U$2:$U$1500,$B$2)/100000/B29) -> 0.28570357 | L29: Brown | M29: =SUMIFS(Sales_Data!$N$2:$N$1500,Sales_Data!$J$2:$J$1500,$L29,Sales_Data!$C$2:$C$1500,">="&DATE(2023,1,1),Sales_Data!$C$2:$C$1500,"<="&DATE(2023,6,1),Sales_Data!$E$2:$E$1500,$B$1)/100000 -> 7.37125 | N29: =SUMIFS(Sales_Data!$N$2:$N$1500,Sales_Data!$J$2:$J$1500,$L29,Sales_Data!$C$2:$C$1500,">="&DATE(2024,1,1),Sales_Data!$C$2:$C$1500,"<="&DATE(2024,6,1),Sales_Data!$E$2:$E$1500,$B$1)/100000 -> 4.38
A30: Red | B30: =SUMIFS(Sales_Data!$N$2:$N$1500,Sales_Data!$J$2:$J$1500,$A30,Sales_Data!$E$2:$E$1500,$B$1,Sales_Data!$U$2:$U$1500,$B$2)/100000 -> 42.03125 | C30: =SUMIFS(Sales_Data!$L$2:$L$1500,Sales_Data!$J$2:$J$1500,$A30,Sales_Data!$E$2:$E$1500,$B$1,Sales_Data!$U$2:$U$1500,$B$2) -> 3900 | D30: =IF(B30=0,0,SUMIFS(Sales_Data!$P$2:$P$1500,Sales_Data!$J$2:$J$1500,$A30,Sales_Data!$E$2:$E$1500,$B$1,Sales_Data!$U$2:$U$1500,$B$2)/100000/B30) -> 0.29072416 | L30: Green | M30: =SUMIFS(Sales_Data!$N$2:$N$1500,Sales_Data!$J$2:$J$1500,$L30,Sales_Data!$C$2:$C$1500,">="&DATE(2023,1,1),Sales_Data!$C$2:$C$1500,"<="&DATE(2023,6,1),Sales_Data!$E$2:$E$1500,$B$1)/100000 -> 5.5225 | N30: =SUMIFS(Sales_Data!$N$2:$N$1500,Sales_Data!$J$2:$J$1500,$L30,Sales_Data!$C$2:$C$1500,">="&DATE(2024,1,1),Sales_Data!$C$2:$C$1500,"<="&DATE(2024,6,1),Sales_Data!$E$2:$E$1500,$B$1)/100000 -> 6.3125
A31: Pink | B31: =SUMIFS(Sales_Data!$N$2:$N$1500,Sales_Data!$J$2:$J$1500,$A31,Sales_Data!$E$2:$E$1500,$B$1,Sales_Data!$U$2:$U$1500,$B$2)/100000 -> 4.3475 | C31: =SUMIFS(Sales_Data!$L$2:$L$1500,Sales_Data!$J$2:$J$1500,$A31,Sales_Data!$E$2:$E$1500,$B$1,Sales_Data!$U$2:$U$1500,$B$2) -> 350 | D31: =IF(B31=0,0,SUMIFS(Sales_Data!$P$2:$P$1500,Sales_Data!$J$2:$J$1500,$A31,Sales_Data!$E$2:$E$1500,$B$1,Sales_Data!$U$2:$U$1500,$B$2)/100000/B31) -> 0.31834388
A32: Black | B32: =SUMIFS(Sales_Data!$N$2:$N$1500,Sales_Data!$J$2:$J$1500,$A32,Sales_Data!$E$2:$E$1500,$B$1,Sales_Data!$U$2:$U$1500,$B$2)/100000 -> 33.4975 | C32: =SUMIFS(Sales_Data!$L$2:$L$1500,Sales_Data!$J$2:$J$1500,$A32,Sales_Data!$E$2:$E$1500,$B$1,Sales_Data!$U$2:$U$1500,$B$2) -> 5050 | D32: =IF(B32=0,0,SUMIFS(Sales_Data!$P$2:$P$1500,Sales_Data!$J$2:$J$1500,$A32,Sales_Data!$E$2:$E$1500,$B$1,Sales_Data!$U$2:$U$1500,$B$2)/100000/B32) -> 0.21866557
A33: Blue / Violet | B33: =SUMIFS(Sales_Data!$N$2:$N$1500,Sales_Data!$J$2:$J$1500,$A33,Sales_Data!$E$2:$E$1500,$B$1,Sales_Data!$U$2:$U$1500,$B$2)/100000 -> 38.67125 | C33: =SUMIFS(Sales_Data!$L$2:$L$1500,Sales_Data!$J$2:$J$1500,$A33,Sales_Data!$E$2:$E$1500,$B$1,Sales_Data!$U$2:$U$1500,$B$2) -> 3025 | D33: =IF(B33=0,0,SUMIFS(Sales_Data!$P$2:$P$1500,Sales_Data!$J$2:$J$1500,$A33,Sales_Data!$E$2:$E$1500,$B$1,Sales_Data!$U$2:$U$1500,$B$2)/100000/B33) -> 0.29922746 | L33: =IF(SUM(M5:M10)=0,"","Like-for-like Jan–Jun: 2023 ₹ "&TEXT(SUM(M5:M10),"0.0")&" L vs 2024 ₹ "&TEXT(SUM(N5:N10),"0.0")&" L ("&TEXT(SUM(N5:N10)/SUM(M5:M10)-1,"+0.0%;-0.0%")&")") -> Like-for-like Jan–Jun: 2023 ₹ 66.6 L vs 2024 ₹ 74.9 L (+12.5%)
A34: Brown | B34: =SUMIFS(Sales_Data!$N$2:$N$1500,Sales_Data!$J$2:$J$1500,$A34,Sales_Data!$E$2:$E$1500,$B$1,Sales_Data!$U$2:$U$1500,$B$2)/100000 -> 18.54 | C34: =SUMIFS(Sales_Data!$L$2:$L$1500,Sales_Data!$J$2:$J$1500,$A34,Sales_Data!$E$2:$E$1500,$B$1,Sales_Data!$U$2:$U$1500,$B$2) -> 2200 | D34: =IF(B34=0,0,SUMIFS(Sales_Data!$P$2:$P$1500,Sales_Data!$J$2:$J$1500,$A34,Sales_Data!$E$2:$E$1500,$B$1,Sales_Data!$U$2:$U$1500,$B$2)/100000/B34) -> 0.25992449
A35: Green | B35: =SUMIFS(Sales_Data!$N$2:$N$1500,Sales_Data!$J$2:$J$1500,$A35,Sales_Data!$E$2:$E$1500,$B$1,Sales_Data!$U$2:$U$1500,$B$2)/100000 -> 16.09 | C35: =SUMIFS(Sales_Data!$L$2:$L$1500,Sales_Data!$J$2:$J$1500,$A35,Sales_Data!$E$2:$E$1500,$B$1,Sales_Data!$U$2:$U$1500,$B$2) -> 1550 | D35: =IF(B35=0,0,SUMIFS(Sales_Data!$P$2:$P$1500,Sales_Data!$J$2:$J$1500,$A35,Sales_Data!$E$2:$E$1500,$B$1,Sales_Data!$U$2:$U$1500,$B$2)/100000/B35) -> 0.29058421
A38: APPLICATION SEGMENT
A39: Segment | B39: Revenue (₹ Lakh) | C39: Qty (kg) | D39: GM %
A40: Metallised Film & Foil Coating | B40: =SUMIFS(Sales_Data!$N$2:$N$1500,Sales_Data!$K$2:$K$1500,$A40,Sales_Data!$E$2:$E$1500,$B$1,Sales_Data!$U$2:$U$1500,$B$2)/100000 -> 48.0525 | C40: =SUMIFS(Sales_Data!$L$2:$L$1500,Sales_Data!$K$2:$K$1500,$A40,Sales_Data!$E$2:$E$1500,$B$1,Sales_Data!$U$2:$U$1500,$B$2) -> 5350 | D40: =IF(B40=0,0,SUMIFS(Sales_Data!$P$2:$P$1500,Sales_Data!$K$2:$K$1500,$A40,Sales_Data!$E$2:$E$1500,$B$1,Sales_Data!$U$2:$U$1500,$B$2)/100000/B40) -> 0.26274387
A41: Wood Stains & Lacquers | B41: =SUMIFS(Sales_Data!$N$2:$N$1500,Sales_Data!$K$2:$K$1500,$A41,Sales_Data!$E$2:$E$1500,$B$1,Sales_Data!$U$2:$U$1500,$B$2)/100000 -> 15.94625 | C41: =SUMIFS(Sales_Data!$L$2:$L$1500,Sales_Data!$K$2:$K$1500,$A41,Sales_Data!$E$2:$E$1500,$B$1,Sales_Data!$U$2:$U$1500,$B$2) -> 1775 | D41: =IF(B41=0,0,SUMIFS(Sales_Data!$P$2:$P$1500,Sales_Data!$K$2:$K$1500,$A41,Sales_Data!$E$2:$E$1500,$B$1,Sales_Data!$U$2:$U$1500,$B$2)/100000/B41) -> 0.27566042
A42: Leather Finishing | B42: =SUMIFS(Sales_Data!$N$2:$N$1500,Sales_Data!$K$2:$K$1500,$A42,Sales_Data!$E$2:$E$1500,$B$1,Sales_Data!$U$2:$U$1500,$B$2)/100000 -> 8.9225 | C42: =SUMIFS(Sales_Data!$L$2:$L$1500,Sales_Data!$K$2:$K$1500,$A42,Sales_Data!$E$2:$E$1500,$B$1,Sales_Data!$U$2:$U$1500,$B$2) -> 1000 | D42: =IF(B42=0,0,SUMIFS(Sales_Data!$P$2:$P$1500,Sales_Data!$K$2:$K$1500,$A42,Sales_Data!$E$2:$E$1500,$B$1,Sales_Data!$U$2:$U$1500,$B$2)/100000/B42) -> 0.27343794
...

Sheet Notes
A1: ABOUT THIS WORKBOOK
A3: Purpose: portfolio sample of a Sales & Operations MIS dashboard for a specialty-chemicals manufacturer.
A4: Product names and C.I. names are taken from the Mansi Solvent Soluble Dyes shade card (37 shades).
A5: All orders, customers (fictional), quantities, prices, costs, lead times and forecasts are SIMULATED.
A6: Period: Jan 2023 – Jun 2024 (200 orders). Currency: INR; 1 Lakh = 100,000.
A8: HOW IT WORKS
A9: Sales_Data = transaction table (blue = input values, black = formulas).
A10: Calc = SUMIFS/INDEX-MATCH summary tables feeding every chart. Forecast Qty column is a blue input.
A11: Dashboard!D4 = Region filter (All / Domestic / Export); Dashboard!H4 = Year filter (All / 2023 / 2024). KPIs and charts recalculate from them.
A12: Domestic-vs-Export donut and Forecast-vs-Actual chart are intentionally not filtered by region.
A14: ASSUMPTIONS
A15: Prices/costs are plausible ranges per shade family (blacks cheapest, blues/pinks highest); gross margin ~25-34%.
... A18: Lead time: domestic 10–15 days promised, export 21–30 days. June 2024 orders include open (undispatched) orders.
